Workbook

Sheet Historic Model
B2: Income Statement | I2: Cash Flow Statement | O2: Balance Sheet
B4: All amounts in million, unless otherwise stated | E4: 2023 | F4: =E4+1 -> 2024 | G4: =F4+1 -> 2025 | I4: All amounts in million, unless otherwise stated | K4: =E$4 -> 2023 | L4: =F$4 -> 2024 | M4: =G$4 -> 2025 | O4: All amounts in million, unless otherwise stated | R4: =S4-1 -> 2022 | S4: =E$4 -> 2023 | T4: =F$4 -> 2024 | U4: =G$4 -> 2025
I6: CASH FROM OPERATIONS | O6: ASSETS
B7: Revenue | E7: 1175229 | F7: 1418582 | G7: 1529130 | I7: Profit from operations (before WC) | K7: 101591 | L7: 170404 | M7: 191832 | O7: CURRENT ASSETS
B8: COGS | E8: -862435 | F8: -997409 | G8: -1074908 | I8: Non-Cash Adjustments | O8: Cash | S8: =K59 -> 334 | T8: =L59 -> 4557 | U8: =M59 -> 780
B9: Gross Profit | E9: =SUM(E7:E8) -> 312794 | F9: =SUM(F7:F8) -> 421173 | G9: =SUM(G7:G8) -> 454222 | I9: Depreciation and amortisation expenses | K9: 28233 | L9: 30223 | M9: 31593 | O9: Inventory | R9: 35331 | S9: 42838 | T9: 41196 | U9: 51230
I10: Finance costs | K10: 1866 | L10: 1932 | M10: 1931 | O10: Receivables | R10: 20301 | S10: 32958 | T10: 46013 | U10: 65377
I11: Interest income | K11: -1852 | L11: -984 | M11: -1475 | O11: Investments | S11: - | T11: 39122 | U11: 55604
B12: SG&A | E12: -203975 | F12: -240655 | G12: -259205 | I12: Dividend income | K12: -268 | L12: -658 | M12: -524 | O12: Other Current Assets | S12: 39869 | T12: 46736 | U12: 59531
B13: EBITDA | E13: =SUM(E9:E12) -> 108819 | F13: =SUM(F9:F12) -> 180518 | G13: =SUM(G9:G12) -> 195017 | I13: Net loss on sale/discarding of PPE | K13: 115 | L13: 481 | M13: 405 | O13: Total Current Assets | S13: =SUM(S8:S12) -> 115999 | T13: =SUM(T8:T12) -> 177624 | U13: =SUM(U8:U12) -> 232522
I14: Net gain on sale of investments in debt MFs | K14: -1809 | L14: -901 | M14: -1060
I15: Fair valuation gain on investment in debt MFs | K15: -17279 | L15: -36005 | M15: -43748 | O15: NON-CURRENT ASSETS
B16: Depreciation | E16: -28233 | F16: -30223 | G16: -31593 | I16: Unrealised foreign exchange (gain)/loss | K16: 209 | L16: -42 | M16: 40 | O16: Property Plant & Equipment | S16: 166666 | T16: 174314 | U16: 236382
B17: EBIT | E17: =SUM(E13:E16) -> 80586 | F17: =SUM(F13:F16) -> 150295 | G17: =SUM(G13:G16) -> 163424 | I17: Subtotal | K17: =SUM(K7:K16) -> 110806 | L17: =SUM(L7:L16) -> 164450 | M17: =SUM(M7:M16) -> 178994 | O17: Right-of-use assets | S17: 5904 | T17: 6129 | U17: 5858
I18: Adjustments for changes in Working Capital: | K18: 3787 | L18: 22777 | M18: -1052 | O18: Capital work-in-progress | S18: 28081 | T18: 63034 | U18: 53575
I19: Cash generated from Operating Activities | K19: =K17+K18 -> 114593 | L19: =L17+L18 -> 187227 | M19: =M17+M18 -> 177942 | O19: Intangible assets | S19: 5479 | T19: 4510 | U19: 4828
B20: Interest Expense | E20: -1866 | F20: -1932 | G20: -1931 | I20: Income Taxes Paid | K20: -22313 | L20: -35557 | M20: -37818 | O20: Intangible assets under development | S20: 889 | T20: 2305 | U20: 4018
B21: EBT | E21: =SUM(E17:E20) -> 78720 | F21: =SUM(F17:F20) -> 148363 | G21: =SUM(G17:G20) -> 161493 | I21: Cash from Operating Activities | K21: =SUM(K19:K20) -> 92280 | L21: =SUM(L19:L20) -> 151670 | M21: =SUM(M19:M20) -> 140124 | O21: Investments | S21: 477564 | T21: 646015 | U21: 689459
O22: Loans | S22: 2 | T22: 1 | U22: 1
I23: CASH FROM INVESTING | O23: Other Assets | S23: 580 | T23: 822 | U23: 871
B24: Current Tax | E24: -22475 | F24: -36311 | G24: -38418 | I24: Fixed assets purchased | K24: -61154 | L24: -67269 | M24: -83486 | O24: Non-current tax assets (Net) | S24: 5729 | T24: 5439 | U24: 4743
B25: Deferred Tax | E25: 1376 | F25: -1999 | G25: -13862 | I25: Fixed assets sold | K25: 987 | L25: 440 | M25: 326 | O25: Deferred tax assets (Net) | S25: 3411 | T25: 1124 | U25: -
B26: Total Tax | E26: =SUM(E24:E25) -> -21099 | F26: =SUM(F24:F25) -> -38310 | G26: =SUM(G24:G25) -> -52280 | I26: Investments Purchased | K26: -638275 | L26: -660967 | M26: -619695 | O26: Other non-current assets | S26: 21483 | T26: 21531 | U26: 23945
B27: Tax Rate | E27: 0.268 | F27: 0.258 | G27: 0.324 | I27: Investments sold | K27: 616054 | L27: 619327 | M27: 598444 | O27: Total Non-Current Assets | R27: =SUM(R7:R26) -> 55632 | S27: =SUM(S16:S26) -> 715788 | T27: =SUM(T16:T26) -> 925224 | U27: =SUM(U16:U26) -> 1023680
I28: Interest received | K28: 1938 | L28: 983 | M28: 1472 | O28: Total Assets | R28: =SUM(R8:R27) -> 111264 | S28: =S13+S27 -> 831787 | T28: =T13+T27 -> 1102848 | U28: =U13+U27 -> 1256202
B29: Net Income | E29: =E21+E26 -> 57621 | F29: =F21+F26 -> 110053 | G29: =G21+G26 -> 109213 | I29: Dividend received | K29: 268 | L29: 658 | M29: 524
I30: Investment in group companies | K30: 0 | L30: 0 | M30: 0 | O30: LIABILITIES
B31: NOPAT | E31: =E17*(1-E27) -> 58988.952 | F31: =F17*(1-F27) -> 111518.89 | G31: =G17*(1-G27) -> 110474.62 | I31: Redemption & cancellation of shares | K31: 0 | L31: 0 | M31: 0 | O31: CURRENT LIABILITIES
B32: Invested Capital | E32: 617982 | F32: 838473 | G32: 942476 | I32: Acquisition of companies | K32: 0 | L32: 0 | M32: 0 | O32: Borrowings | S32: 12158 | T32: 331 | U32: -
I33: Inter corporate deposits | K33: 0 | L33: 0 | M33: 0 | O33: Lease Liabilities | S33: 66 | T33: 178 | U33: 226
I34: Other investing items | K34: 0 | L34: 0 | M34: 0 | O34: Trade Payables | R34: 97610 | S34: 117804 | T34: 145824 | U34: 174211
O35: Other Current Liablities | S35: 49361 | T35: 58858 | U35: 65610
K36: =SUM(K24:K35) -> -80182 | L36: =SUM(L24:L35) -> -106828 | M36: =SUM(M24:M35) -> -102415 | O36: Provisions | S36: 10038 | T36: 12066 | U36: 14423
O37: Net Tax Liabilities | R37: 11104 | S37: 11566 | T37: 12030 | U37: 12737
I38: CASH FROM FINANCING | O38: Total Current Liabilities | S38: =SUM(S32:S37) -> 200993 | T38: =SUM(T32:T37) -> 229287 | U38: =SUM(U32:U37) -> 267207
I39: Proceeds from shares | K39: - | L39: - | M39: -
I40: Redemption of debentures | K40: - | L40: - | M40: - | O40: NON CURRENT LIABILITIES
I41: Proceeds from borrowings | K41: 8339 | L41: - | M41: - | O41: Lease liabilities | S41: 249 | T41: 677 | U41: 538
I42: Repayment of borrowings | K42: - | L42: -11827 | M42: -331 | O42: Provisions | S42: 876 | T42: 1448 | U42: 1260
I43: Interest paid (finance cost paid) | K43: -1854 | L43: -1472 | M43: -1578 | O43: Deferred tax liabilities (Net) | S43: 0 | T43: 0 | U43: 12911
...

Sheet Ratios
A1: Return Ratios
B3: 2023F | C3: 2024F | D3: 2025F | E3: Average
A4: ROA | B4: ='Historic Model'!E29/'Historic Model'!S28 -> 0.069273744 | C4: ='Historic Model'!F29/'Historic Model'!T28 -> 0.099789817 | D4: ='Historic Model'!G29/'Historic Model'!U28 -> 0.086939043 | E4: =AVERAGE(B4:D4) -> 0.085334202
A5: ROE | B5: ='Historic Model'!E29/'Historic Model'!S53 -> 0.095427445 | C5: ='Historic Model'!F29/'Historic Model'!T53 -> 0.13104356 | D5: ='Historic Model'!G29/'Historic Model'!U53 -> 0.11612635 | E5: =AVERAGE(B5:D5) -> 0.11419912
A6: ROIC | B6: ='Historic Model'!E31/'Historic Model'!E32 -> 0.095454159 | C6: ='Historic Model'!F31/'Historic Model'!F32 -> 0.13300236 | D6: ='Historic Model'!G31/'Historic Model'!G32 -> 0.11721744 | E6: =AVERAGE(B6:D6) -> 0.11522465
A8: Profitability Ratios
B10: 2023F | C10: 2024F | D10: 2025F | E10: Average
A11: Gross Profit Margin | B11: ='Historic Model'!E9/'Historic Model'!E7 -> 0.26615579 | C11: ='Historic Model'!F9/'Historic Model'!F7 -> 0.29689718 | D11: ='Historic Model'!G9/'Historic Model'!G7 -> 0.29704603 | E11: =AVERAGE(B11:D11) -> 0.28669967
A12: Expense Ratios | B12: =-SUM('Historic Model'!E8,'Historic Model'!E12)/'Historic Model'!E7 -> 0.90740613 | C12: =-SUM('Historic Model'!F8,'Historic Model'!F12)/'Historic Model'!F7 -> 0.87274757 | D12: =-SUM('Historic Model'!G8,'Historic Model'!G12)/'Historic Model'!G7 -> 0.87246539 | E12: =AVERAGE(B12:D12) -> 0.88420636
A13: Effective Tax Rate | B13: =-'Historic Model'!E26/'Historic Model'!E21 -> 0.26802591 | C13: =-'Historic Model'!F26/'Historic Model'!F21 -> 0.25821802 | D13: =-'Historic Model'!G26/'Historic Model'!G21 -> 0.3237292 | E13: =AVERAGE(B13:D13) -> 0.28332438
A14: Tax Burden | B14: ='Historic Model'!E29/'Historic Model'!E21 -> 0.73197409 | C14: ='Historic Model'!F29/'Historic Model'!F21 -> 0.74178198 | D14: ='Historic Model'!G29/'Historic Model'!G21 -> 0.6762708 | E14: =AVERAGE(B14:D14) -> 0.71667562
A15: Interest Burden | B15: ='Historic Model'!E21/'Historic Model'!E17 -> 0.97684461 | C15: ='Historic Model'!F21/'Historic Model'!F17 -> 0.98714528 | D15: ='Historic Model'!G21/'Historic Model'!G17 -> 0.98818411 | E15: =AVERAGE(B15:D15) -> 0.984058
A16: Effective Interest Rate | B16: =1-B15 -> 0.023155387 | C16: =1-C15 -> 0.012854719 | D16: =1-D15 -> 0.01181589 | E16: =AVERAGE(B16:D16) -> 0.015941999
A18: Asset Utilization Ratios
B20: 2023F | C20: 2024F | D20: 2025F | E20: Average
A21: Asset Turnover | B21: ='Historic Model'!E7/'Historic Model'!S28 -> 1.4128966 | C21: ='Historic Model'!F7/'Historic Model'!T28 -> 1.2862897 | D21: ='Historic Model'!G7/'Historic Model'!U28 -> 1.2172644 | E21: =AVERAGE(B21:D21) -> 1.3054836
A22: PPE Turnover | B22: ='Historic Model'!E7/'Historic Model'!S16 -> 7.0514022 | C22: ='Historic Model'!F7/'Historic Model'!T16 -> 8.1380841 | D22: ='Historic Model'!G7/'Historic Model'!U16 -> 6.4688936 | E22: =AVERAGE(B22:D22) -> 7.21946
A23: A/R Turnover | B23: ='Historic Model'!E7/'Historic Model'!S10 -> 35.658383 | C23: ='Historic Model'!F7/'Historic Model'!T10 -> 30.830026 | D23: ='Historic Model'!G7/'Historic Model'!U10 -> 23.389418 | E23: =AVERAGE(B23:D23) -> 29.959276
A24: A/R Days | B24: =('Historic Model'!S10*365)/'Historic Model'!E7 -> 10.236022 | C24: =('Historic Model'!T10*365)/'Historic Model'!F7 -> 11.839108 | D24: =('Historic Model'!U10*365)/'Historic Model'!G7 -> 15.605347 | E24: =AVERAGE(B24:D24) -> 12.560159
A25: Inventory Turnover | B25: =-'Historic Model'!E8/'Historic Model'!S9 -> 20.132476 | C25: =-'Historic Model'!F8/'Historic Model'!T9 -> 24.211307 | D25: =-'Historic Model'!G8/'Historic Model'!U9 -> 20.982003 | E25: =AVERAGE(B25:D25) -> 21.775262
A26: Inventory Days | B26: =('Historic Model'!S9*365)/(-'Historic Model'!E8) -> 18.129911 | C26: =('Historic Model'!T9*365)/(-'Historic Model'!F8) -> 15.075601 | D26: =('Historic Model'!U9*365)/(-'Historic Model'!G8) -> 17.395861 | E26: =AVERAGE(B26:D26) -> 16.867124
A27: A/P Turnover | B27: =-'Historic Model'!E8/'Historic Model'!S34 -> 7.3209314 | C27: =-'Historic Model'!F8/'Historic Model'!T34 -> 6.8398137 | D27: =-'Historic Model'!G8/'Historic Model'!U34 -> 6.17015 | E27: =AVERAGE(B27:D27) -> 6.776965
A28: A/P Days | B28: =('Historic Model'!S34*365)/(-'Historic Model'!E8) -> 49.857044 | C28: =('Historic Model'!T34*365)/(-'Historic Model'!F8) -> 53.364026 | D28: =('Historic Model'!U34*365)/(-'Historic Model'!G8) -> 59.155774 | E28: =AVERAGE(B28:D28) -> 54.125615
A29: Cash Conversion Cycle / WC Funding Gap | B29: =(B23+B25)-B28 -> 5.9338149 | C29: =(C23+C25)-C28 -> 1.677307 | D29: =(D23+D25)-D28 -> -14.784353 | E29: =AVERAGE(B29:D29) -> -2.3910771
A31: Leverage Analysis
B33: 2023F | C33: 2024F | D33: 2025F | E33: Average
A34: Total Asset to Equity | B34: ='Historic Model'!S28/'Historic Model'!S53 -> 1.3775413 | C34: ='Historic Model'!T28/'Historic Model'!T53 -> 1.3131957 | D34: ='Historic Model'!U28/'Historic Model'!U53 -> 1.3357215 | E34: =AVERAGE(B34:D34) -> 1.3421528
A35: Total Liabilities to Equity | B35: ='Historic Model'!S48/'Historic Model'!S53 -> 0.37754132 | C35: ='Historic Model'!T48/'Historic Model'!T53 -> 0.31319568 | D35: ='Historic Model'!U48/'Historic Model'!U53 -> 0.33572151 | E35: =AVERAGE(B35:D35) -> 0.34215284
A36: Debt to Equity | B36: =('Historic Model'!S32+'Historic Model'!S33+'Historic Model'!S41)/'Historic Model'!S53 -> 0.020656818 | C36: =('Historic Model'!T32+'Historic Model'!T33+'Historic Model'!T41)/'Historic Model'!T53 -> 0.0014122074 | D36: =('Historic Model'!U33+'Historic Model'!U41)/'Historic Model'!U53 -> 0.00081236237 | E36: =AVERAGE(B36:D36) -> 0.0076271293
A37: Debt to EBITDA | B37: =('Historic Model'!S32+'Historic Model'!S33+'Historic Model'!S41)/('Historic Model'!S53-('Historic Model'!S19+'Historic Model'!S20)) -> 0.020876991 | C37: =('Historic Model'!T32+'Historic Model'!T33+'Historic Model'!T41)/('Historic Model'!T53-('Historic Model'!T19+'Historic Model'!T20)) -> 0.001423761 | D37: =('Historic Model'!U33+'Historic Model'!U41)/('Historic Model'!U53-('Historic Model'!U19+'Historic Model'!U20)) -> 0.00082007598 | E37: =AVERAGE(B37:D37) -> 0.0077069426
A38: Net Debt to EBITDA | B38: =('Historic Model'!S32+'Historic Model'!S33+'Historic Model'!S41-'Historic Model'!S8)/'Historic Model'!E13 -> 0.11155221 | C38: =('Historic Model'!T32+'Historic Model'!T33+'Historic Model'!T41-'Historic Model'!T8)/'Historic Model'!F13 -> -0.018674038 | D38: =('Historic Model'!U33+'Historic Model'!U41-'Historic Model'!U8)/'Historic Model'!G13 -> -8.2044129e-05 | E38: =AVERAGE(B38:D38) -> 0.030932043
A40: Liquidity Analysis
B42: 2023F | C42: 2024F | D42: 2025F | E42: Average
A43: Current Ratio | B43: ='Historic Model'!S13/'Historic Model'!S38 -> 0.57712955 | C43: ='Historic Model'!T13/'Historic Model'!T38 -> 0.77467977 | D43: ='Historic Model'!U13/'Historic Model'!U38 -> 0.87019427 | E43: =AVERAGE(B43:D43) -> 0.74066786
A44: Quick Ratio | B44: =('Historic Model'!S13-'Historic Model'!S9)/'Historic Model'!S38 -> 0.36399775 | C44: =('Historic Model'!T13-'Historic Model'!T9)/'Historic Model'!T38 -> 0.59500975 | D44: =('Historic Model'!U13-'Historic Model'!U9)/'Historic Model'!U38 -> 0.67847025 | E44: =AVERAGE(B44:D44) -> 0.54582592
A45: Interest Coverage | B45: =-'Historic Model'!E13/(+'Historic Model'!E20) -> 58.31672 | C45: =-'Historic Model'!F13/(+'Historic Model'!F20) -> 93.435818 | D45: =-'Historic Model'!G13/(+'Historic Model'!G20) -> 100.99275 | E45: =AVERAGE(B45:D45) -> 84.248429
A48: DuPont Pyramid 3 Step Check
B50: 2023F | C50: 2024F | D50: 2025F
A51: Net Profit Margin | B51: ='Historic Model'!E29/'Historic Model'!E7 -> 0.049029593 | C51: ='Historic Model'!F29/'Historic Model'!F7 -> 0.077579583 | D51: ='Historic Model'!G29/'Historic Model'!G7 -> 0.071421658
A52: Asset Turnover | B52: ='Historic Model'!E7/'Historic Model'!S28 -> 1.4128966 | C52: ='Historic Model'!F7/'Historic Model'!T28 -> 1.2862897 | D52: ='Historic Model'!G7/'Historic Model'!U28 -> 1.2172644
...

Sheet Assumptions and Drivers
A2: Assumptions & Drivers
A4: All figures in USD thousands unless stated | C4: FY2023 | D4: FY2024 | E4: FY2025 | F4: FY2026 | G4: FY2027 | H4: FY2028 | I4: FY2029 | J4: FY2030
A6: Days in Period | C6: 365 | D6: 365 | E6: 365 | F6: 365 | G6: 365 | H6: 365 | I6: 365 | J6: 365
A8: Income Statement
A9: Sales Growth | D9: =('Historic Model'!F7/'Historic Model'!E7)-1 -> 0.20706858 | E9: =('Historic Model'!G7/'Historic Model'!F7)-1 -> 0.077928523 | F9: 0.07 | G9: 0.065 | H9: 0.06 | I9: 0.055 | J9: 0.055
A10: Gross Margin | C10: =Ratios!B11 -> 0.26615579 | D10: =Ratios!C11 -> 0.29689718 | E10: =Ratios!D11 -> 0.29704603 | F10: 0.29 | G10: 0.288 | H10: 0.285 | I10: 0.285 | J10: 0.285
A11: SG&A (Fixed Cost) | C11: =-'Historic Model'!E12 -> 203975 | D11: =-'Historic Model'!F12 -> 240655 | E11: =-'Historic Model'!G12 -> 259205 | F11: =F12*Forecasting!F6 -> 274876.41 | G11: =G12*Forecasting!G6 -> 289258.34 | H11: =H12*Forecasting!H6 -> 304766.76 | I11: =I12*Forecasting!I6 -> 321528.94 | J11: =J12*Forecasting!J6 -> 339213.03
A12: SG&A (Percentof Sales) | C12: =-'Historic Model'!E12/'Historic Model'!E7 -> 0.17356192 | D12: =-'Historic Model'!F12/'Historic Model'!F7 -> 0.16964476 | E12: =-'Historic Model'!G12/'Historic Model'!G7 -> 0.16951142 | F12: 0.168 | G12: 0.166 | H12: 0.165 | I12: 0.165 | J12: 0.165
A13: Depreciation (Percent of Sales) | C13: =('Historic Model'!E16/'Historic Model'!E7)*-1 -> 0.024023403 | D13: =('Historic Model'!F16/'Historic Model'!F7)*-1 -> 0.021305078 | E13: =('Historic Model'!G16/'Historic Model'!G7)*-1 -> 0.020660768 | F13: =E13 -> 0.020660768 | G13: =F13 -> 0.020660768 | H13: =G13 -> 0.020660768 | I13: =H13 -> 0.020660768 | J13: =I13 -> 0.020660768
A14: Long-Term Debt Interest Rate (Average Debt) | C14: =(-'Historic Model'!E20/Forecasting!C141)*0.1 -> 0.16586667 | D14: =(-'Historic Model'!F20/Forecasting!D141)*0.1 -> 0.11889231 | E14: =(-'Historic Model'!G20/Forecasting!E141)*0.1 -> 0.098445068 | F14: 0.11 | G14: 0.11 | H14: 0.11 | I14: 0.11 | J14: 0.11
A15: Tax Rate (Percent of EBT) | C15: =-'Historic Model'!E26/'Historic Model'!E21 -> 0.26802591 | D15: =-'Historic Model'!F26/'Historic Model'!F21 -> 0.25821802 | E15: =-'Historic Model'!G26/'Historic Model'!G21 -> 0.3237292 | F15: 0.26 | G15: 0.26 | H15: 0.26 | I15: 0.26 | J15: 0.26
A16: Tax Expense | F16: =F15*Forecasting!F18 -> 45992.749 | G16: =G15*Forecasting!G18 -> 49959.141 | H16: =H15*Forecasting!H18 -> 50056.24 | I16: =I15*Forecasting!I18 -> 51798.862 | J16: =J15*Forecasting!J18 -> 53047.078
A17: Balance Sheet
A18: Capital Asset Turnover Ratio | B18: (x) | C18: =Forecasting!C6/Forecasting!C38 -> 7.0514022 | D18: =Forecasting!D6/Forecasting!D38 -> 8.1380841 | E18: =Forecasting!E6/Forecasting!E38 -> 6.4688936 | F18: 6 | G18: 6 | H18: 6 | I18: 6 | J18: 6
A19: Receivable Days (Sales Basis) | B19: (Days) | C19: =Ratios!B24 -> 10.236022 | D19: =Ratios!C24 -> 11.839108 | E19: =Ratios!D24 -> 15.605347 | F19: 15 | G19: 15 | H19: 15 | I19: 15 | J19: 15
A20: Inventory Days (COGS Basis) | B20: (Days) | C20: =Ratios!B26 -> 18.129911 | D20: =Ratios!C26 -> 15.075601 | E20: =Ratios!D26 -> 17.395861 | F20: 17 | G20: 17 | H20: 17 | I20: 17 | J20: 17
A21: Payable Days (COGS Basis) | B21: (Days) | C21: =('Historic Model'!S34/'Historic Model'!E8)*365*-1 -> 49.857044 | D21: =('Historic Model'!T34/'Historic Model'!F8)*365*-1 -> 53.364026 | E21: =('Historic Model'!U34/'Historic Model'!G8)*365*-1 -> 59.155774 | F21: 57 | G21: 57 | H21: 57 | I21: 57 | J21: 57
A22: Income Tax Payable (Percent of Taxes) | C22: =('Historic Model'!S37/'Historic Model'!E26)*-1 -> 0.54817764 | D22: =('Historic Model'!T37/'Historic Model'!F26)*-1 -> 0.31401723 | E22: =('Historic Model'!U37/'Historic Model'!G26)*-1 -> 0.24363045 | F22: 0.25 | G22: 0.25 | H22: 0.25 | I22: 0.25 | J22: 0.25
A23: Long Term Debt | C23: =Forecasting!C49 -> 1125 | D23: =Forecasting!D49 -> 2125 | E23: =Forecasting!E49 -> 1798 | F23: 1800 | G23: 1800 | H23: 1800 | I23: 1800 | J23: 1800
A24: Common Share Capital | C24: ='Historic Model'!S51 -> 1510 | D24: ='Historic Model'!T51 -> 1572 | E24: ='Historic Model'!U51 -> 1572 | F24: =E24 -> 1572 | G24: =F24 -> 1572 | H24: =G24 -> 1572 | I24: =H24 -> 1572 | J24: =I24 -> 1572
A25: Dividend Payout Ratio | C25: =C26/'Historic Model'!E29 -> 0.31455546 | D25: =D26/'Historic Model'!F29 -> 0.24703552 | E25: =E26/'Historic Model'!G29 -> 0.35984727 | F25: 0.3 | G25: 0.3 | H25: 0.3 | I25: 0.3 | J25: 0.3
A26: Dividends Paid | C26: =-'Historic Model'!K44 -> 18125 | D26: =-'Historic Model'!L44 -> 27187 | E26: =-'Historic Model'!M44 -> 39300 | F26: =F27*F25 -> 39270.732 | G26: =G27*G25 -> 42657.42 | H26: =H27*H25 -> 42740.328 | I26: =I27*I25 -> 44228.259 | J26: =J27*J25 -> 45294.043
A27: Net Income | C27: =Forecasting!C21 -> 57621 | D27: =Forecasting!D21 -> 110053 | E27: =Forecasting!E21 -> 109213 | F27: =Forecasting!F21 -> 130902.44 | G27: =Forecasting!G21 -> 142191.4 | H27: =Forecasting!H21 -> 142467.76 | I27: =Forecasting!I21 -> 147427.53 | J27: =Forecasting!J21 -> 150980.14
A28: Base Cash | F28: 5000 | G28: 5000 | H28: 5000 | I28: 5000 | J28: 5000
A29: Total Cash | F29: 77453.585 | G29: 120329.35 | H29: 165074.46 | I29: 214714.8 | J29: 263858.85
A30: Excess Cash | F30: =MAX(0,F29-F28) -> 72453.585 | G30: =MAX(0,G29-G28) -> 115329.35 | H30: =MAX(0,H29-H28) -> 160074.46 | I30: =MAX(0,I29-I28) -> 209714.8 | J30: =MAX(0,J29-J28) -> 258858.85
A31: Long-Term Debt

Sheet Forecasting
A2: Income Statement
A4: All amounts in million, unless otherwise stated | C4: FY2023 | D4: FY2024 | E4: FY2025 | F4: FY2026 | G4: FY2027 | H4: FY2028 | I4: FY2029 | J4: FY2030
A6: Revenues | C6: ='Historic Model'!E7 -> 1175229 | D6: ='Historic Model'!F7 -> 1418582 | E6: ='Historic Model'!G7 -> 1529130 | F6: =E6*(1+'Assumptions and Drivers'!F9) -> 1636169.1 | G6: =F6*(1+'Assumptions and Drivers'!G9) -> 1742520.1 | H6: =G6*(1+'Assumptions and Drivers'!H9) -> 1847071.3 | I6: =H6*(1+'Assumptions and Drivers'!I9) -> 1948660.2 | J6: =I6*(1+'Assumptions and Drivers'!J9) -> 2055836.5
A7: Cost of Goods Sold | C7: ='Historic Model'!E8 -> -862435 | D7: ='Historic Model'!F8 -> -997409 | E7: ='Historic Model'!G8 -> -1074908 | F7: =-(1-'Assumptions and Drivers'!D10)*Forecasting!F6 -> -1150395.1 | G7: =-(1-'Assumptions and Drivers'!E10)*Forecasting!G6 -> -1224911.4 | H7: =-(1-'Assumptions and Drivers'!F10)*Forecasting!H6 -> -1311420.6 | I7: =-(1-'Assumptions and Drivers'!G10)*Forecasting!I6 -> -1387446.1 | J7: =-(1-'Assumptions and Drivers'!H10)*Forecasting!J6 -> -1469923.1
A8: Gross Profit | C8: =SUM(C6:C7) -> 312794 | D8: =SUM(D6:D7) -> 421173 | E8: =SUM(E6:E7) -> 454222 | F8: =SUM(F6:F7) -> 485774 | G8: =SUM(G6:G7) -> 517608.68 | H8: =SUM(H6:H7) -> 535650.68 | I8: =SUM(I6:I7) -> 561214.14 | J8: =SUM(J6:J7) -> 585913.41
Q9: FY2023 | R9: FY2024 | S9: FY2025 | T9: FY2026 | U9: FY2027 | V9: FY2028 | W9: FY2029 | X9: FY2030
A10: SG&A | C10: ='Historic Model'!E12 -> -203975 | D10: ='Historic Model'!F12 -> -240655 | E10: ='Historic Model'!G12 -> -259205 | F10: =-'Assumptions and Drivers'!F11 -> -274876.41 | G10: =-'Assumptions and Drivers'!G11 -> -289258.34 | H10: =-'Assumptions and Drivers'!H11 -> -304766.76 | I10: =-'Assumptions and Drivers'!I11 -> -321528.94 | J10: =-'Assumptions and Drivers'!J11 -> -339213.03 | P10: Minimum Cash Balance | Q10: 7000 | R10: 50000 | S10: 50000 | T10: 50000 | U10: 50000 | V10: 50000 | W10: 50000 | X10: 50000
A11: EBITDA | C11: =SUM(C8:C10) -> 108819 | D11: =SUM(D8:D10) -> 180518 | E11: =SUM(E8:E10) -> 195017 | F11: =SUM(F8:F10) -> 210897.59 | G11: =SUM(G8:G10) -> 228350.34 | H11: =SUM(H8:H10) -> 230883.91 | I11: =SUM(I8:I10) -> 239685.21 | J11: =SUM(J8:J10) -> 246700.38 | P11: Excess Cash Balance | Q11: =C31-Q10 -> -6666 | R11: =D31-R10 -> -45443 | S11: =E31-S10 -> -49220 | T11: =F31-T10 -> -45000 | U11: =G31-U10 -> -45000 | V11: =H31-V10 -> -45000 | W11: =I31-W10 -> -45000 | X11: =J31-X10 -> -45000
A13: Research and Development | C13: 0 | D13: 0 | E13: 0 | F13: 0 | G13: 0 | H13: 0 | I13: 0 | J13: 0
A14: Depreciation | C14: ='Historic Model'!E16 -> -28233 | D14: ='Historic Model'!F16 -> -30223 | E14: ='Historic Model'!G16 -> -31593 | F14: =F127 -> -33804.51 | G14: =G127 -> -36001.803 | H14: =H127 -> -38161.911 | I14: =I127 -> -40260.816 | J14: =J127 -> -42475.161
A15: EBIT (Operating Profit) | C15: =SUM(C11:C14) -> 80586 | D15: =SUM(D11:D14) -> 150295 | E15: =SUM(E11:E14) -> 163424 | F15: =SUM(F11:F14) -> 177093.08 | G15: =SUM(G11:G14) -> 192348.54 | H15: =SUM(H11:H14) -> 192722 | I15: =SUM(I11:I14) -> 199424.39 | J15: =SUM(J11:J14) -> 204225.22
A17: Interest | C17: ='Historic Model'!E20 -> -1866 | D17: ='Historic Model'!F20 -> -1932 | E17: ='Historic Model'!G20 -> -1931 | F17: =-F144 -> -197.89 | G17: =-G144 -> -198 | H17: =-H144 -> -198 | I17: =-I144 -> -198 | J17: =-J144 -> -198
A18: Earnings Before Taxes | C18: =SUM(C15:C17) -> 78720 | D18: =SUM(D15:D17) -> 148363 | E18: =SUM(E15:E17) -> 161493 | F18: =SUM(F15:F17) -> 176895.19 | G18: =SUM(G15:G17) -> 192150.54 | H18: =SUM(H15:H17) -> 192524 | I18: =SUM(I15:I17) -> 199226.39 | J18: =SUM(J15:J17) -> 204027.22
A20: Taxes | C20: ='Historic Model'!E26 -> -21099 | D20: ='Historic Model'!F26 -> -38310 | E20: ='Historic Model'!G26 -> -52280 | F20: =-F18*'Assumptions and Drivers'!F15 -> -45992.749 | G20: =-G18*'Assumptions and Drivers'!G15 -> -49959.141 | H20: =-H18*'Assumptions and Drivers'!H15 -> -50056.24 | I20: =-I18*'Assumptions and Drivers'!I15 -> -51798.862 | J20: =-J18*'Assumptions and Drivers'!J15 -> -53047.078
A21: Net Income | C21: =SUM(C18:C20) -> 57621 | D21: =SUM(D18:D20) -> 110053 | E21: =SUM(E18:E20) -> 109213 | F21: =SUM(F18:F20) -> 130902.44 | G21: =SUM(G18:G20) -> 142191.4 | H21: =SUM(H18:H20) -> 142467.76 | I21: =SUM(I18:I20) -> 147427.53 | J21: =SUM(J18:J20) -> 150980.14
A23: Common Dividends | C23: ='Assumptions and Drivers'!C26 -> 18125 | D23: ='Assumptions and Drivers'!D26 -> 27187 | E23: ='Assumptions and Drivers'!E26 -> 39300 | F23: ='Assumptions and Drivers'!F26 -> 39270.732 | G23: ='Assumptions and Drivers'!G26 -> 42657.42 | H23: ='Assumptions and Drivers'!H26 -> 42740.328 | I23: ='Assumptions and Drivers'!I26 -> 44228.259 | J23: ='Assumptions and Drivers'!J26 -> 45294.043
A26: Balance Sheet
A28: All amounts in million, unless otherwise stated | C28: FY2023 | D28: FY2024 | E28: FY2025 | F28: FY2026 | G28: FY2027 | H28: FY2028 | I28: FY2029 | J28: FY2030
A30: ASSETS
A31: Cash | C31: =C88 -> 334 | D31: =D88 -> 4557 | E31: =E88 -> 780 | F31: ='Assumptions and Drivers'!F28 -> 5000 | G31: ='Assumptions and Drivers'!G28 -> 5000 | H31: ='Assumptions and Drivers'!H28 -> 5000 | I31: ='Assumptions and Drivers'!I28 -> 5000 | J31: ='Assumptions and Drivers'!J28 -> 5000
A32: Trade and Other Receivables | C32: ='Historic Model'!S10 -> 32958 | D32: ='Historic Model'!T10 -> 46013 | E32: ='Historic Model'!U10 -> 65377 | F32: =(F6*F102)/365 -> 67239.826 | G32: =(G6*G102)/365 -> 71610.415 | H32: =(H6*H102)/365 -> 75907.04 | I32: =(I6*I102)/365 -> 80081.927 | J32: =(J6*J102)/365 -> 84486.433
A33: Inventories | C33: ='Historic Model'!S9 -> 42838 | D33: ='Historic Model'!T9 -> 41196 | E33: ='Historic Model'!U9 -> 51230 | F33: =(F99*F103)/365 -> 53580.046 | G33: =(G99*G103)/365 -> 57050.668 | H33: =(H99*H103)/365 -> 61079.865 | I33: =(I99*I103)/365 -> 64620.776 | J33: =(J99*J103)/365 -> 68462.173
A34: Investments | C34: ='Historic Model'!S11 -> - | D34: ='Historic Model'!T11 -> 39122 | E34: ='Historic Model'!U11 -> 55604 | F34: =(F6*5%)+('Assumptions and Drivers'!F30*40%) -> 110789.89 | G34: =(G6*5%)+('Assumptions and Drivers'!G30*40%) -> 133257.74 | H34: =(H6*5%)+('Assumptions and Drivers'!H30*40%) -> 156383.35 | I34: =(I6*5%)+('Assumptions and Drivers'!I30*40%) -> 181318.93 | J34: =(J6*5%)+('Assumptions and Drivers'!J30*40%) -> 206335.36
A35: Other Current Assets | C35: ='Historic Model'!S12 -> 39869 | D35: ='Historic Model'!T12 -> 46736 | E35: ='Historic Model'!U12 -> 59531 | F35: =(E35*(1+3%))+('Assumptions and Drivers'!F30*30%) -> 83053.006 | G35: =(F35*(1+3%))+('Assumptions and Drivers'!G30*20%) -> 108610.47 | H35: =(G35*(1+3%))+('Assumptions and Drivers'!H30*20%) -> 143883.67 | I35: =(H35*(1+3%))+('Assumptions and Drivers'!I30*20%) -> 190143.14 | J35: =(I35*(1+3%))+('Assumptions and Drivers'!J30*20%) -> 247619.2
A36: Total Current Assets | C36: =SUM(C31:C35) -> 115999 | D36: =SUM(D31:D35) -> 177624 | E36: =SUM(E31:E35) -> 232522 | F36: =SUM(F31:F35) -> 319662.77 | G36: =SUM(G31:G35) -> 375529.29 | H36: =SUM(H31:H35) -> 442253.92 | I36: =SUM(I31:I35) -> 521164.78 | J36: =SUM(J31:J35) -> 611903.17
A38: Property Plant and Equipment | C38: ='Historic Model'!S16 -> 166666 | D38: ='Historic Model'!T16 -> 174314 | E38: ='Historic Model'!U16 -> 236382 | F38: =F128 -> 272694.85 | G38: =G128 -> 290420.02 | H38: =H128 -> 307845.22 | I38: =I128 -> 324776.7 | J38: =J128 -> 342639.42
A39: Non-Current Assets | C39: =SUM('Historic Model'!S17:S26) -> 549122 | D39: =SUM('Historic Model'!T17:T26) -> 750910 | E39: =SUM('Historic Model'!U17:U26) -> 787298 | F39: =(F6*47%)+('Assumptions and Drivers'!F30*30%) -> 790735.55 | G39: =(G6*47%)+('Assumptions and Drivers'!G30*30%) -> 853583.25 | H39: =(H6*47%)+('Assumptions and Drivers'!H30*30%) -> 916145.85 | I39: =(I6*47%)+('Assumptions and Drivers'!I30*30%) -> 978784.74 | J39: =(J6*47%)+('Assumptions and Drivers'!J30*30%) -> 1043900.8
A40: TOTAL ASSETS | C40: =SUM(C36:C39) -> 831787 | D40: =SUM(D36:D39) -> 1102848 | E40: =SUM(E36:E39) -> 1256202 | F40: =SUM(F36:F39) -> 1383093.2 | G40: =SUM(G36:G39) -> 1519532.6 | H40: =SUM(H36:H39) -> 1666245 | I40: =SUM(I36:I39) -> 1824726.2 | J40: =SUM(J36:J39) -> 1998443.4
A42: LIABILITIES
A43: Borrowings and Lease Liabilities | C43: =SUM('Historic Model'!S32:S33) -> 12224 | D43: =SUM('Historic Model'!T32:T33) -> 509 | E43: =SUM('Historic Model'!U32:U33) -> 226 | F43: =E43*50% -> 113 | G43: =F43*50% -> 56.5 | H43: 0 | I43: 0 | J43: 0
A44: Trade and Other Payables | C44: ='Historic Model'!S34 -> 117804 | D44: ='Historic Model'!T34 -> 145824 | E44: ='Historic Model'!U34 -> 174211 | F44: =(F99*F104)/365 -> 179650.74 | G44: =(G99*G104)/365 -> 191287.54 | H44: =(H99*H104)/365 -> 204797.19 | I44: =(I99*I104)/365 -> 216669.66 | J44: =(J99*J104)/365 -> 229549.64
A45: Income Taxes Payable | C45: ='Historic Model'!S37 -> 11566 | D45: ='Historic Model'!T37 -> 12030 | E45: ='Historic Model'!U37 -> 12737 | F45: =F111 -> 11498.187 | G45: =G111 -> 12489.785 | H45: =H111 -> 12514.06 | I45: =I111 -> 12949.715 | J45: =J111 -> 13261.769
A46: Other Liabilities | C46: =SUM('Historic Model'!S35:S36) -> 59399 | D46: =SUM('Historic Model'!T35:T36) -> 70924 | E46: =SUM('Historic Model'!U35:U36) -> 80033 | F46: =F6*6.4% -> 104714.82 | G46: =G6*6.4% -> 111521.29 | H46: =H6*6.4% -> 118212.56 | I46: =I6*6.4% -> 124714.25 | J46: =J6*6.4% -> 131573.54
A47: Total Current Liabilities | C47: =SUM(C43:C46) -> 200993 | D47: =SUM(D43:D46) -> 229287 | E47: =SUM(E43:E46) -> 267207 | F47: =SUM(F43:F46) -> 295976.75 | G47: =SUM(G43:G46) -> 315355.11 | H47: =SUM(H43:H46) -> 335523.82 | I47: =SUM(I43:I46) -> 354333.63 | J47: =SUM(J43:J46) -> 374384.95
A49: Long-Term Debt | C49: =SUM('Historic Model'!S41:S42) -> 1125 | D49: =SUM('Historic Model'!T41:T42) -> 2125 | E49: =SUM('Historic Model'!U41:U42) -> 1798 | F49: ='Assumptions and Drivers'!F23 -> 1800 | G49: ='Assumptions and Drivers'!G23 -> 1800 | H49: ='Assumptions and Drivers'!H23 -> 1800 | I49: ='Assumptions and Drivers'!I23 -> 1800 | J49: ='Assumptions and Drivers'!J23 -> 1800
A50: Other Non-Current Liabilities | C50: =SUM('Historic Model'!S43:S44) -> 25849 | D50: =SUM('Historic Model'!T43:T44) -> 31616 | E50: =SUM('Historic Model'!U43:U44) -> 46730 | F50: =E50*(1+1.5%) -> 47430.95 | G50: =F50*(1+1.5%) -> 48142.414 | H50: =G50*(1+1.5%) -> 48864.55 | I50: =H50*(1+1.5%) -> 49597.519 | J50: =I50*(1+1.5%) -> 50341.482
A51: Total Liabilities | C51: =SUM(C47:C50) -> 227967 | D51: =SUM(D47:D50) -> 263028 | E51: =SUM(E47:E50) -> 315735 | F51: =SUM(F47:F50) -> 345207.7 | G51: =SUM(G47:G50) -> 365297.52 | H51: =SUM(H47:H50) -> 386188.37 | I51: =SUM(I47:I50) -> 405731.15 | J51: =SUM(J47:J50) -> 426526.43
A53: EQUITY
A54: Common Stock and Additional Paid-In Capital | C54: ='Assumptions and Drivers'!C24 -> 1510 | D54: ='Assumptions and Drivers'!D24 -> 1572 | E54: ='Assumptions and Drivers'!E24 -> 1572 | F54: ='Assumptions and Drivers'!F24 -> 1572 | G54: ='Assumptions and Drivers'!G24 -> 1572 | H54: ='Assumptions and Drivers'!H24 -> 1572 | I54: ='Assumptions and Drivers'!I24 -> 1572 | J54: ='Assumptions and Drivers'!J24 -> 1572
A55: Retained Earnings | C55: 541980 | D55: 646509 | E55: 746003 | F55: =F159 -> 837634.71 | G55: =G159 -> 937168.69 | H55: =H159 -> 1036896.1 | I55: =I159 -> 1140095.4 | J55: =J159 -> 1245781.5
...

Sheet Charts and Graphs
A2: Charts & Graphs
A4: All amounts in million, unless otherwise stated | C4: FY2023 | D4: FY2024 | E4: FY2025 | F4: FY2026 | G4: FY2027 | H4: FY2028 | I4: FY2029 | J4: FY2030
A6: Income Statement
A7: Revenue | C7: =Forecasting!C6 -> 1175229 | D7: =Forecasting!D6 -> 1418582 | E7: =Forecasting!E6 -> 1529130 | F7: =Forecasting!F6 -> 1636169.1 | G7: =Forecasting!G6 -> 1742520.1 | H7: =Forecasting!H6 -> 1847071.3 | I7: =Forecasting!I6 -> 1948660.2 | J7: =Forecasting!J6 -> 2055836.5
A8: EBITDA | C8: =Forecasting!C11 -> 108819 | D8: =Forecasting!D11 -> 180518 | E8: =Forecasting!E11 -> 195017 | F8: =Forecasting!F11 -> 210897.59 | G8: =Forecasting!G11 -> 228350.34 | H8: =Forecasting!H11 -> 230883.91 | I8: =Forecasting!I11 -> 239685.21 | J8: =Forecasting!J11 -> 246700.38
A9: EBITDA Margin | C9: =C8/C7 -> 0.092593869 | D9: =D8/D7 -> 0.12725243 | E9: =E8/E7 -> 0.12753461 | F9: =F8/F7 -> 0.12889718 | G9: =G8/G7 -> 0.13104603 | H9: =H8/H7 -> 0.125 | I9: =I8/I7 -> 0.123 | J9: =J8/J7 -> 0.12
A11: Net Income | C11: =Forecasting!C21 -> 57621 | D11: =Forecasting!D21 -> 110053 | E11: =Forecasting!E21 -> 109213 | F11: =Forecasting!F21 -> 130902.44 | G11: =Forecasting!G21 -> 142191.4 | H11: =Forecasting!H21 -> 142467.76 | I11: =Forecasting!I21 -> 147427.53 | J11: =Forecasting!J21 -> 150980.14
A12: Net Income Margin | C12: =C11/C7 -> 0.049029593 | D12: =D11/D7 -> 0.077579583 | E12: =E11/E7 -> 0.071421658 | F12: =F11/F7 -> 0.080005446 | G12: =G11/G7 -> 0.081601011 | H12: =H11/H7 -> 0.077131706 | I12: =I11/I7 -> 0.075655842 | J12: =J11/J7 -> 0.073439762
A14: Cash Flow
A15: Operating | C15: =Forecasting!C74 -> 86346 | D15: =Forecasting!D74 -> 157347 | E15: =Forecasting!E74 -> 140502 | F15: =Forecasting!F74 -> 164695.01 | G15: =Forecasting!G74 -> 182980.38 | H15: =Forecasting!H74 -> 185837.78 | I15: =Forecasting!I74 -> 192280.67 | J15: =Forecasting!J74 -> 198401.43
A16: Investing | C16: =Forecasting!C78 -> -61154 | D16: =Forecasting!D78 -> -67269 | E16: =Forecasting!E78 -> -83486 | F16: =Forecasting!F78 -> -70117.36 | G16: =Forecasting!G78 -> -53726.968 | H16: =Forecasting!H78 -> -55587.112 | I16: =Forecasting!I78 -> -57192.303 | J16: =Forecasting!J78 -> -60337.88
A17: Financing | C17: =Forecasting!C84 -> -18125 | D17: =Forecasting!D84 -> -26125 | E17: =Forecasting!E84 -> -39627 | F17: =Forecasting!F84 -> -39268.732 | G17: =Forecasting!G84 -> -42657.42 | H17: =Forecasting!H84 -> -42740.328 | I17: =Forecasting!I84 -> -44228.259 | J17: =Forecasting!J84 -> -45294.043
A18: Change in Cash | C18: =SUM(C15:C17) -> 7067 | D18: =SUM(D15:D17) -> 63953 | E18: =SUM(E15:E17) -> 17389 | F18: =SUM(F15:F17) -> 55308.915 | G18: =SUM(G15:G17) -> 86595.995 | H18: =SUM(H15:H17) -> 87510.343 | I18: =SUM(I15:I17) -> 90860.108 | J18: =SUM(J15:J17) -> 92769.511
L19: `
A21: Income Statement | F21: Cash Flow Statement

Sheet Model-R
B3: Income Statement
B5: All figures in USD thousands | F5: 2023 | G5: =F5+1 -> 2024 | H5: =G5+1 -> 2025 | J5: Learner | K5: Correct | L5: Compare
B8: Revenue | F8: 58000 | G8: 62000 | H8: 65000
B9: COGS | F9: -30000 | G9: -31000 | H9: -32000
B10: Gross Profit | F10: =SUM('Historic Model'!E7:E8) -> 312794 | G10: =SUM('Historic Model'!F7:F8) -> 421173 | H10: =SUM('Historic Model'!G7:G8) -> 454222 | J10: =SUM('Historic Model'!E9:G9) -> 1188189 | K10: =SUM(F10:H10) -> 1188189 | L10: {=IF(SUM(ISBLANK('Historic Model'!E9:G9)*1)>0,0,IF(J10=K10,1,0))} -> 1
B13: SG&A | F13: -6000 | G13: -7000 | H13: -8000
B14: Other | F14: -2000 | G14: -2000 | H14: -2000
B15: EBITDA | F15: ='Historic Model'!E9+SUM('Historic Model'!E12:E12) -> 108819 | G15: ='Historic Model'!F9+SUM('Historic Model'!F12:F12) -> 180518 | H15: ='Historic Model'!G9+SUM('Historic Model'!G12:G12) -> 195017 | J15: =SUM('Historic Model'!E13:G13) -> 484354 | K15: =SUM(F15:H15) -> 484354 | L15: {=IF(SUM(ISBLANK('Historic Model'!E13:G13)*1)>0,0,IF(J15=K15,1,0))} -> 1
B18: Depreciation | F18: -4000 | G18: -4000 | H18: -4000
B19: EBIT | F19: ='Historic Model'!E16+'Historic Model'!E13 -> 80586 | G19: ='Historic Model'!F16+'Historic Model'!F13 -> 150295 | H19: ='Historic Model'!G16+'Historic Model'!G13 -> 163424 | J19: =SUM('Historic Model'!E17:G17) -> 394305 | K19: =SUM(F19:H19) -> 394305 | L19: {=IF(SUM(ISBLANK('Historic Model'!E17:G17)*1)>0,0,IF(J19=K19,1,0))} -> 1
B22: Interest Expense | F22: -6000 | G22: -6000 | H22: -6000
B23: EBT | F23: ='Historic Model'!E20+'Historic Model'!E17 -> 78720 | G23: ='Historic Model'!F20+'Historic Model'!F17 -> 148363 | H23: ='Historic Model'!G20+'Historic Model'!G17 -> 161493 | J23: =SUM('Historic Model'!E21:G21) -> 388576 | K23: =SUM(F23:H23) -> 388576 | L23: {=IF(SUM(ISBLANK('Historic Model'!E21:G21)*1)>0,0,IF(J23=K23,1,0))} -> 1
B26: Current Tax | F26: -1000 | G26: -1000 | H26: -1000
B27: Deferred Tax | F27: -2000 | G27: -2000 | H27: -2000
B28: Total Tax | F28: =SUM('Historic Model'!E24:E25) -> -21099 | G28: =SUM('Historic Model'!F24:F25) -> -38310 | H28: =SUM('Historic Model'!G24:G25) -> -52280 | J28: =SUM('Historic Model'!E26:G26) -> -111689 | K28: =SUM(F28:H28) -> -111689 | L28: {=IF(SUM(ISBLANK('Historic Model'!E26:G26)*1)>0,0,IF(J28=K28,1,0))} -> 1
B31: Net Income | F31: ='Historic Model'!E26+'Historic Model'!E21 -> 57621 | G31: ='Historic Model'!F26+'Historic Model'!F21 -> 110053 | H31: ='Historic Model'!G26+'Historic Model'!G21 -> 109213 | J31: =SUM('Historic Model'!E29:G29) -> 276887 | K31: =SUM(F31:H31) -> 276887 | L31: {=IF(SUM(ISBLANK('Historic Model'!E29:G29)*1)>0,0,IF(J31=K31,1,0))} -> 1
B35: Cash Flow Statement
B37: All figures in USD thousands | F37: =F$5 -> 2023 | G37: =G$5 -> 2024 | H37: =H$5 -> 2025 | J37: Learner | K37: Correct | L37: Compare
B39: CASH FROM OPERATIONS
B40: Net Income | F40: ='Historic Model'!E29 -> 57621 | G40: ='Historic Model'!F29 -> 110053 | H40: ='Historic Model'!G29 -> 109213 | J40: =SUM('Historic Model'!#REF!) -> #REF! | K40: =SUM(F40:H40) -> 276887 | L40: {=IF(SUM(ISBLANK('Historic Model'!#REF!)*1)>0,0,IF(J40=K40,1,0))} -> #REF!
B41: Depreciation | F41: =-'Historic Model'!E16 -> 28233 | G41: =-'Historic Model'!F16 -> 30223 | H41: =-'Historic Model'!G16 -> 31593 | J41: =SUM('Historic Model'!#REF!) -> #REF! | K41: =SUM(F41:H41) -> 90049 | L41: {=IF(SUM(ISBLANK('Historic Model'!#REF!)*1)>0,0,IF(J41=K41,1,0))} -> #REF!
B42: Deferred Tax | F42: =-'Historic Model'!E25 -> -1376 | G42: =-'Historic Model'!F25 -> 1999 | H42: =-'Historic Model'!G25 -> 13862 | J42: =SUM('Historic Model'!#REF!) -> #REF! | K42: =SUM(F42:H42) -> 14485 | L42: {=IF(SUM(ISBLANK('Historic Model'!#REF!)*1)>0,0,IF(J42=K42,1,0))} -> #REF!
B43: Cash from Accounts Receivable | F43: 1000 | G43: 1000 | H43: 1000
B44: Cash from Inventory | F44: -1000 | G44: -1000 | H44: -1000
B45: Cash from Accounts Payable | F45: 1000 | G45: 1000 | H45: 1000
B46: Subtotal | F46: =SUM('Historic Model'!K7:K10) -> 131690 | G46: =SUM('Historic Model'!L7:L10) -> 202559 | H46: =SUM('Historic Model'!M7:M10) -> 225356 | J46: =SUM('Historic Model'!K17:M17) -> 454250 | K46: =SUM(F46:H46) -> 559605 | L46: {=IF(SUM(ISBLANK('Historic Model'!K17:M17)*1)>0,0,IF(J46=K46,1,0))} -> 0
B49: CASH FROM INVESTING
B50: Capital Expenditure | F50: -4000 | G50: -4000 | H50: -4000
B51: Subtotal | F51: ='Historic Model'!K35 -> 0 | G51: ='Historic Model'!L35 -> 0 | H51: ='Historic Model'!M35 -> 0 | J51: =SUM('Historic Model'!#REF!) -> #REF! | K51: =SUM(F51:H51) -> 0 | L51: {=IF(SUM(ISBLANK('Historic Model'!#REF!)*1)>0,0,IF(J51=K51,1,0))} -> #REF!
B54: CASH FROM FINANCING
B55: Line of Credit Issue / (Repay) | F55: -1000 | G55: -2000 | H55: -1000
B56: Term Loan Issue / (Repay) | F56: -3000 | G56: -3000 | H56: -3000
B57: Equity Issue / (Buyback) | F57: 1000 | G57: 0 | H57: 0
B58: Payment of Dividends | F58: -1000 | G58: -1000 | H58: -1000
B59: Subtotal | F59: =SUM('Historic Model'!K40:K46) -> -12084 | G59: =SUM('Historic Model'!L40:L46) -> -40619 | H59: =SUM('Historic Model'!M40:M46) -> -41486 | J59: =SUM('Historic Model'!K47:M47) -> -94189 | K59: =SUM(F59:H59) -> -94189 | L59: {=IF(SUM(ISBLANK('Historic Model'!K47:M47)*1)>0,0,IF(J59=K59,1,0))} -> 1
B62: CASH BALANCE
B63: Beginning | F63: ='Historic Model'!R8 -> 0 | G63: ='Historic Model'!K59 -> 334 | H63: ='Historic Model'!L59 -> 4557 | J63: =SUM('Historic Model'!K57:M57) -> 5211 | K63: =SUM(F63:H63) -> 4891 | L63: {=IF(SUM(ISBLANK('Historic Model'!K57:M57)*1)>0,0,IF(J63=K63,1,0))} -> 0
B64: Change in Cash | F64: ='Historic Model'!K17+'Historic Model'!#REF!+'Historic Model'!K47 -> #REF! | G64: ='Historic Model'!L17+'Historic Model'!#REF!+'Historic Model'!L47 -> #REF! | H64: ='Historic Model'!M17+'Historic Model'!#REF!+'Historic Model'!M47 -> #REF! | J64: =SUM('Historic Model'!K58:M58) -> 460 | K64: =SUM(F64:H64) -> #REF! | L64: {=IF(SUM(ISBLANK('Historic Model'!K58:M58)*1)>0,0,IF(J64=K64,1,0))} -> #REF!
B65: Ending | F65: =SUM('Historic Model'!K57:K58) -> 334 | G65: =SUM('Historic Model'!L57:L58) -> 4557 | H65: =SUM('Historic Model'!M57:M58) -> 780 | J65: =SUM('Historic Model'!K59:M59) -> 5671 | K65: =SUM(F65:H65) -> 5671 | L65: {=IF(SUM(ISBLANK('Historic Model'!K59:M59)*1)>0,0,IF(J65=K65,1,0))} -> 1
B69: Balance Sheet
...
